Workbook

Sheet Resumo
A1: PLANILHA DE ESTIMATIVA DE HORAS PARA PROJETOS DE IMPLANTAÇÃO CLOVER CRM
B2: Parâmetros Gerais: | J2: Formato dos Treinamentos: | R2: Nome do Cliente:
B3: Número total de usuários licenciados | C3: 25 | J3: Treinamento Adm, Configuração e Simulações: | N3: Presencial | R3: <Digite o nome do cliente aqui>
B4: Fator p/ Gestão de Projeto | C4: 0.08 | J4: Treinamento Operacional e Go-Live: | N4: Presencial
B5: ERP do cliente | C5: ALIARE - SOLUTION | J5: Número de administradores: | N5: 1
B6: Método de integração do Aliare Integra | C6: API padrão ERP | J6: Número de usuários operacionais (vendedores): | N6: 5 | P6: Qtde Tumas Gestores
B7: Será usado ambiente de produção e homologação? | C7: NÃO | J7: Número de gestores: | N7: 1 | P7: =(ROUNDUP(N7/N9,0))*N10 -> 1 | R7: Regras para treinamentos: Treinamentos presenciais: 20 pessoas por turma, a partir de 25 pessoas será contabilizados 2 consultores. Treinamentos remotos: 10 pessoas por turma.
B8: O projeto será na Cloud Aliare? | C8: SIM | J8: Tamanho das Turmas p/ Treinamento Operacional: | N8: 25 | P8: Qtd Tumas Operac.
B9: Fases de implantação | C9: 1 | J9: Tamanho das Turmas p/ Treinamento Gestor: | N9: 10 | P9: =(ROUNDUP(N6/N8,0))*N10 -> 1 | W9: 1 | X9: consultor | Y9: 2 | Z9: consultores
B10: Coeficiente de complexidade (multi-empresa) | C10: 1 | J10: Em quantas etapas ocorrerá o Go-Live por fase: | N10: 1 | W10: 24 | Y10: 25
A12: Escopo Cliente (x) | B12: Módulos do Clover | C12: Estimativa de Horas do Projeto de Implantação
C13: Instalação dos sistemas | D13: Definição de regras, processos, layouts e documentação | E13: Integração de Dados Técnica | H13: Validação de dados da integração | K13: Parametrização | N13: Treinamento Adm., Config. e Simulação | O13: Validação do ambiente + testes funcionais | R13: Go-Live | S13: Acompanhamento Go-Live | T13: Pós-Produção
E14: Total | F14: Homologação | G14: Produção | H14: Total | I14: Homologação | J14: Produção | K14: Total | L14: Homologação | M14: Produção | O14: Total | P14: Homologação | Q14: Produção
A15: x | B15: CRM - MM - Funcionalidades Fundamentais | C15: =Funcionalidades!H2 -> 1 | D15: =IF(A15="x", Funcionalidades!$M$3, "") -> 5.2899 | E15: =IF(A15<>"x", "", IF(C6<>"Sem integração",(IF(AND(OR(C5="ALIARE - AGB",C5="SIMER",C5="ALIARE - SOLUTION"),C6="API padrão ERP"),Funcionalidades!I2,IF(AND(C5="ALIARE - AGB",C6="Integração (antiga)"),#REF!,IF(AND(OR(C5<>"ALIARE - AGB",C5<>"SIMER",C5<>"ALIARE - SOLUTION"),C6="API padrão ERP"),'Aliare Integra ERP Terceiro'!B117*24,Funcionalidades!I2)))),0))*'AGBCLOVER-Listagem dos fluxos'!$G$14 -> 20 | F15: 0 | G15: =IF($A$15 = "x", IF($C$7 = "SIM",$E$15*0.3, E15),"0,00") -> 20 | H15: =IF(A15="x", Funcionalidades!L2, "") -> 17.2689 | I15: =IF(A15 = "x", IF($C$7 = "SIM",H15*0.7, " "), " ") | J15: =IF(A15 = "x", IF($C$7 = "SIM",H15*0.3, H15)," ") -> 17.2689 | K15: =IF(A15="x", Funcionalidades!$N$3, "") -> 5.2899 | L15: =IF(A15 = "x", IF($C$7 = "SIM",K15*0.7, " "), K15) | M15: =IF(A15 = "x", IF($C$7 = "SIM",K15*0.3, K15), " ") -> 5.2899 | N15: =IF(A15="x", Funcionalidades!$O$3, "") -> 10.5171 | O15: =IF(A15="x", Funcionalidades!$P$3, "") -> 2.6466 | P15: =IF(A15 = "x", IF($C$7 = "SIM",O15*0.7, " "), O15) | Q15: =IF(A15 = "x", IF($C$7 = "SIM",O15*0.3, O15)," ") -> 2.6466 | R15: =IF($A15="x", Funcionalidades!$Q$3, "") -> 3.9666 | S15: =8*$C$9*N10 -> 8 | T15: 12
B16: CRM - MM - Registro de Visita | D16: =IF(A16="x", Funcionalidades!$M$100, "") | K16: =IF(A16="x", Funcionalidades!$N$100, "") | L16: =IF(A16 = "x", IF($C$7 = "SIM",K16*0.7, " "), K16) | M16: =IF(A16 = "x", IF($C$7 = "SIM",K16*0.3, K16), " ") | N16: =IF(A16="x", Funcionalidades!$O$100, "") | O16: =IF(A16="x", Funcionalidades!$P$100, "") | P16: =IF(A16 = "x", IF($C$7 = "SIM",O16*0.7, " "), O16) | Q16: =IF(A16 = "x", IF($C$7 = "SIM",O16*0.3, O16)," ") | R16: =IF(A16="x", Funcionalidades!$Q$100, "")
B17: CRM - MM - Potencial & Metas | D17: =IF(A17="x", Funcionalidades!$M$126, "") | K17: =IF(A17="x", Funcionalidades!$N$126, "") | L17: =IF(A17 = "x", IF($C$7 = "SIM",K17*0.7, " "), K17) | M17: =IF(A17 = "x", IF($C$7 = "SIM",K17*0.3, K17), " ") | N17: =IF(A17="x", Funcionalidades!$O$126, "") | O17: =IF(A17="x", Funcionalidades!$P$126, "") | P17: =IF(A17 = "x", IF($C$7 = "SIM",O17*0.7, " "), O17) | Q17: =IF(A17 = "x", IF($C$7 = "SIM",O17*0.3, O17)," ") | R17: =IF(A17="x", Funcionalidades!$Q$126, "")
B18: CRM - MM - Segmentação | D18: =IF(A18="x", Funcionalidades!$M$216, "") | K18: =IF(A18="x", Funcionalidades!$N$216, "") | L18: =IF(A18 = "x", IF($C$7 = "SIM",K18*0.7, " "), K18) | M18: =IF(A18 = "x", IF($C$7 = "SIM",K18*0.3, K18), " ") | N18: =IF(A18="x", Funcionalidades!$O$216, "") | O18: =IF(A18="x", Funcionalidades!$P$216, "") | P18: =IF(A18 = "x", IF($C$7 = "SIM",O18*0.7, " "), O18) | Q18: =IF(A18 = "x", IF($C$7 = "SIM",O18*0.3, O18)," ") | R18: =IF(A18="x", Funcionalidades!$Q$216, "")
B19: CRM - MM - Previsão de Vendas | D19: =IF(A19="x", Funcionalidades!$M$231, "") | K19: =IF(A19="x", Funcionalidades!$N$231, "") | L19: =IF(A19 = "x", IF($C$7 = "SIM",K19*0.7, " "), K19) | M19: =IF(A19 = "x", IF($C$7 = "SIM",K19*0.3, K19), " ") | N19: =IF(A19="x", Funcionalidades!$O$231, "") | O19: =IF(A19="x", Funcionalidades!$P$231, "") | P19: =IF(A19 = "x", IF($C$7 = "SIM",O19*0.7, " "), O19) | Q19: =IF(A19 = "x", IF($C$7 = "SIM",O19*0.3, O19)," ") | R19: =IF(A19="x", Funcionalidades!$Q$231, "")
B20: CRM - MM - Analise de Vendas | D20: =IF(A20="x", Funcionalidades!$M$264, "") | K20: =IF(A20="x", Funcionalidades!$N$264, "") | L20: =IF(A20 = "x", IF($C$7 = "SIM",K20*0.7, " "), K20) | M20: =IF(A20 = "x", IF($C$7 = "SIM",K20*0.3, K20), " ") | N20: =IF(A20="x", Funcionalidades!$O$264, "") | O20: =IF(A20="x", Funcionalidades!$P$264, "") | P20: =IF(A20 = "x", IF($C$7 = "SIM",O20*0.7, " "), O20) | Q20: =IF(A20 = "x", IF($C$7 = "SIM",O20*0.3, O20)," ") | R20: =IF(A20="x", Funcionalidades!$Q$264, "")
B21: CRM - MM - Potencial Maquinas | D21: =IF(A21="x", Funcionalidades!$M$274, "") | K21: =IF(A21="x", Funcionalidades!$N$274, "") | L21: =IF(A21 = "x", IF($C$7 = "SIM",K21*0.7, " "), K21) | M21: =IF(A21 = "x", IF($C$7 = "SIM",K21*0.3, K21), " ") | N21: =IF(A21="x", Funcionalidades!$O$274, "") | O21: =IF(A21="x", Funcionalidades!$P$274, "") | P21: =IF(A21 = "x", IF($C$7 = "SIM",O21*0.7, " "), O21) | Q21: =IF(A21 = "x", IF($C$7 = "SIM",O21*0.3, O21)," ") | R21: =IF(A21="x", Funcionalidades!$Q$274, "")
B22: CRM - MM - Chamados | D22: =IF(A22="x", Funcionalidades!$M$294, "") | K22: =IF(A22="x", Funcionalidades!$N$294, "") | L22: =IF(A22 = "x", IF($C$7 = "SIM",K22*0.7, " "), K22) | M22: =IF(A22 = "x", IF($C$7 = "SIM",K22*0.3, K22), " ") | N22: =IF(A22="x", Funcionalidades!$O$294, "") | O22: =IF(A22="x", Funcionalidades!$P$294, "") | P22: =IF(A22 = "x", IF($C$7 = "SIM",O22*0.7, " "), O22) | Q22: =IF(A22 = "x", IF($C$7 = "SIM",O22*0.3, O22)," ") | R22: =IF(A22="x", Funcionalidades!$Q$294, "")
A23: x | B23: CRM - MM - Força de Vendas | D23: =IF(A23="x", Funcionalidades!$M$142, "") -> 5.9895 | K23: =IF(A23="x", Funcionalidades!$N$142, "") -> 11.979 | L23: =IF(A23 = "x", IF($C$7 = "SIM",K23*0.7, " "), K23) | M23: =IF(A23 = "x", IF($C$7 = "SIM",K23*0.3, K23), " ") -> 11.979 | N23: =IF(A23="x", Funcionalidades!$O$142, "") -> 8.9865 | O23: =IF(A23="x", Funcionalidades!$P$142, "") -> 3.06 | P23: =IF(A23 = "x", IF($C$7 = "SIM",O23*0.7, " "), O23) | Q23: =IF(A23 = "x", IF($C$7 = "SIM",O23*0.3, O23)," ") -> 3.06 | R23: =IF(A23="x", Funcionalidades!$Q$142, "") -> 2.997
B24: CRM - MM - Viagem | D24: =IF(A24="x", Funcionalidades!$M$193, "") | K24: =IF(A24="x", Funcionalidades!$N$193, "") | L24: =IF(A24 = "x", IF($C$7 = "SIM",K24*0.7, " "), K24) | M24: =IF(A24 = "x", IF($C$7 = "SIM",K24*0.3, K24), " ") | N24: =IF(A24="x", Funcionalidades!$O$193, "") | O24: =IF(A24="x", Funcionalidades!$P$193, "") | P24: =IF(A24 = "x", IF($C$7 = "SIM",O24*0.7, " "), O24) | Q24: =IF(A24 = "x", IF($C$7 = "SIM",O24*0.3, O24)," ") | R24: =IF(A24="x", Funcionalidades!$Q$193, "")
B25: CRM - MM - Funil de Vendas | D25: =IF(A25="x", Funcionalidades!$M$248, "") | K25: =IF(A25="x", Funcionalidades!$N$248, "") | L25: =IF(A25 = "x", IF($C$7 = "SIM",K25*0.7, " "), K25) | M25: =IF(A25 = "x", IF($C$7 = "SIM",K25*0.3, K25), " ") | N25: =IF(A25="x", Funcionalidades!$O$248, "") | O25: =IF(A25="x", Funcionalidades!$P$248, "") | P25: =IF(A25 = "x", IF($C$7 = "SIM",O25*0.7, " "), O25) | Q25: =IF(A25 = "x", IF($C$7 = "SIM",O25*0.3, O25)," ") | R25: =IF(A25="x", Funcionalidades!$Q$248, "")
B26: CRM - MM - Proposta de Crédito | D26: =IF(A26="x", Funcionalidades!M222, "") | K26: =IF(A26="x", Funcionalidades!$N$222, "") | L26: =IF(A26 = "x", IF($C$7 = "SIM",K26*0.7, " "), K26) | M26: =IF(A26 = "x", IF($C$7 = "SIM",K26*0.3, K26), " ") | N26: =IF(A26="x", Funcionalidades!$O$222, "") | O26: =IF(A26="x", Funcionalidades!$P$222, "") | P26: =IF(A26 = "x", IF($C$7 = "SIM",O26*0.7, " "), O26) | Q26: =IF(A26 = "x", IF($C$7 = "SIM",O26*0.3, O26)," ") | R26: =IF(A26="x", Funcionalidades!$Q$222, "")
B27: CRM - MM - Ordem de Serviço | D27: =IF(A27="x", Funcionalidades!$M$239, "") | K27: =IF(A27="x", Funcionalidades!$N$239, "") | L27: =IF(A27 = "x", IF($C$7 = "SIM",K27*0.7, " "), K27) | M27: =IF(A27 = "x", IF($C$7 = "SIM",K27*0.3, K27), " ") | N27: =IF(A27="x", Funcionalidades!$O$239, "") | O27: =IF(A27="x", Funcionalidades!$P$239, "") | P27: =IF(A27 = "x", IF($C$7 = "SIM",O27*0.7, " "), O27) | Q27: =IF(A27 = "x", IF($C$7 = "SIM",O27*0.3, O27)," ") | R27: =IF(A27="x", Funcionalidades!$Q$239, "")
A28: =COUNTIF(A15:A27,"x") -> 2 | B28: TOTAL | C28: =C15 -> 1 | D28: =SUM(D15:D27) -> 11.2794 | F28: =SUM(F15:F27) -> 0 | G28: =SUM(G15:G27) -> 20 | I28: =SUM(I15:I27) -> 0 | J28: =SUM(J15:J27) -> 17.2689 | L28: =SUM(L15:L27) -> 0 | M28: =SUM(M15:M27) -> 17.2689 | N28: =SUM(N15:N27) -> 19.5036 | P28: =SUM(P15:P27) -> 0 | Q28: =SUM(Q15:Q27) -> 5.7066 | R28: =SUM(R15:R27) -> 6.9636 | S28: =$S$15 -> 8 | T28: =$T$15 -> 12
B30: SERVIÇOS
B31: Especialidade | C31: Horas Estimadas | D31: %
B32: Gerenciamento de Projeto | C32: =ROUNDUP(SUM(C34:C36)*C4,0) -> 10 | D32: =C32/$C$37 -> 0.07751938
B33: Instalação | C33: =ROUNDUP(C28,0) -> 1 | D33: =C33/$C$37 -> 0.007751938
B34: Implantação | C34: =ROUNDUP(SUM($D$28,$L$28:$T$28,$I$28:$J$28),0) -> 98 | D34: =C34/$C$37 -> 0.75968992
B35: Integração Técnica | C35: =ROUNDUP(SUM(F28:G28),0) -> 20 | D35: =C35/$C$37 -> 0.15503876
B36: Adequações | C36: =D42 -> 0 | D36: =C36/$C$37 -> 0
B37: TOTAL | C37: =SUM(C32:C36) -> 129 | D37: =SUM(D32:D36) -> 1
A40: Tarefa | B40: Descrição | D40: Horas
A41: 1 | B41: Adequações | D41: 0
C42: TOTAL | D42: =SUM(D41:D41) -> 0
L159: = SE(E(A101="x";D109="x"); 0; SE(E(A314='Resumo'!A23"x";OU(D314="x";D315="x";D316="x")); 0;'Aliare Integra AGB'!G24))

Sheet Funcionalidades
A1: TOTAL ESTIMADO DE HORAS (s/ horas de gestão de projeto) | F1: =SUM(G2+H2+I2) -> 99 | G1: C&S CRM | H1: instalação | I1: Integração de Dados | J1: Fluxos de Integração | K1: Tabelas Integradas | L1: Validação de Dados | M1: LRP | N1: Parametrização | O1: Simulação e Treinamento | P1: Validação de Ambiente | Q1: Go Live | R1: Acomp. Go Live | S1: Pós-produção
B2: Módulo | C2: Funcionalidade Mãe | D2: Contratado? | E2: Funcionalidade Filha | F2: Tipo de funcionalidade | G2: =SUM(G3+G100+G126+G142+G193+G216+G222+G231+G239+G248) -> 78 | H2: =("01:00:00" + (IF(Resumo!$C$5 = "ALIARE - AGB","05:00:00","00:00:00")) + (IF(Resumo!$C$7 = "SIM","04:00:00","00:00:00")))*24 -> 1 | I2: =SUM(I3,I100,I126,I142,I193,I216,I222,I231,I239,I248,I264,I274) -> 20 | L2: =(L3+L100+L126+L142+L193+L216+L222+L231+L239+L248) -> 17.2689 | M2: =SUM(M3,M100,M142,M193,M216,M222,M231,M239,M248) -> 9.966 | N2: =SUM(N3,N100,N126,N142,N193,N216,N222,N231,N239,N248) -> 17.2689 | O2: =SUM(O3,O100,O126,O142,O193,O216,O222,O231,O239,O248) -> 19.5036 | P2: =SUM(P3,P100,P126,P142,P193,P216,P222,P231,P239,P248) -> 5.7066 | Q2: =SUM(Q3,Q100,Q126,Q142,Q193,Q216,Q222,Q231,Q239,Q248) -> 6.9636 | R2: =SUM(R3,R100,R126,R142,R193,R216,R222,R231,R239) -> 0 | S2: =SUM(S3,S100,S126,S142,S193,S216,S222,S231,S239,S248) -> 0
B3: CRM - MM - Funcionalidades Fundamentais | G3: =ROUNDUP(IF($A$4="x", SUMIF($D$4:$D$99,"x",$G$4:$G$99) * 24, 0),0) -> 33 | I3: =ROUNDUP(IF($A$4="x",SUMIF($D$4:$D$99,"x",$I$4:$I$99)*24,0),0) -> 6 | L3: =G3*0.1603 + IF(Resumo!C7 = "SIM",(G3*0.1603)*0.3,0) -> 5.2899 | M3: =$G$3*0.1603 -> 5.2899 | N3: =$G$3*0.1603 + IF(Resumo!$C$7="SIM", $G$3*0.1603*0.3, 0) -> 5.2899 | O3: =$G$3*0.3187 -> 10.5171 | P3: =$G$3*0.0802 + IF(Resumo!$C$7 = "SIM",($G$3*0.0802*0.3),0) -> 2.6466 | Q3: =($G$3*0.1202)*Resumo!P9 -> 3.9666 | R3: =$G$3*0 -> 0 | S3: 0
A4: =IF(Resumo!A15="x",Resumo!A15,"") -> x | C4: Cadastros Fundamentais | D4: x | E4: Empresa/Filial | F4: Obrigatório | G4: 0.041666667 | J4: =IF(OR(Resumo!$C$5="ALIARE - AGB", Resumo!$C$5="SIMER",Resumo!$C$5="ALIARE - SOLUTION"), _xlfn.CONCAT('Aliare Integra Solution'!$A$15," + ",'Aliare Integra Solution'!$A$18), _xlfn.CONCAT('Aliare Integra ERP Terceiro'!$A$15,"+",'Aliare Integra ERP Terceiro'!$A$18)) -> Cadastro básico – Empresa + Cadastro básico - Filial | K4: =IF(Resumo!$C$5="ALIARE - SOLUTION", _xlfn.CONCAT('Aliare Integra Solution'!$B$15,"+",'Aliare Integra Solution'!$B$18), _xlfn.CONCAT('Aliare Integra ERP Terceiro'!$B$15,"+",'Aliare Integra ERP Terceiro'!$B$18)) -> 1.14 Empresa+1.15 Filial
D5: x | E5: Grupo Empresarial | F5: Obrigatório | G5: 0.013888889
D6: x | E6: Unidade Federativa | F6: Obrigatório | G6: 0.020833333 | J6: =IF(OR(Resumo!$C$5="ALIARE - AGB", Resumo!$C$5="SIMER",Resumo!$C$5="ALIARE - SOLUTION"), 'Aliare Integra Solution'!$A$6,'Aliare Integra ERP Terceiro'!$A$6) -> Cadastro básico - País, Estado e Cidade | K6: =IF(Resumo!$C$5="ALIARE - SOLUTION", 'Aliare Integra Solution'!$B$6, 'Aliare Integra ERP Terceiro'!$B$6) -> 1.01 País
D7: x | E7: País | F7: Obrigatório | G7: 0.0069444444 | K7: =IF(Resumo!$C$5="ALIARE - SOLUTION", 'Aliare Integra Solution'!$B$7, 'Aliare Integra ERP Terceiro'!$B$7) -> 1.02 Unidade Federativa
D8: x | E8: Cidade | F8: Obrigatório | G8: 0.0069444444 | K8: =IF(Resumo!$C$5="ALIARE - SOLUTION", 'Aliare Integra Solution'!$B$8, 'Aliare Integra ERP Terceiro'!$B$8) -> 1.03 Cidade
D9: x | E9: Unidade de medida | F9: Opcional | G9: 0.020833333 | J9: =IF(OR(Resumo!$C$5="ALIARE - AGB", Resumo!$C$5="SIMER",Resumo!$C$5="ALIARE - SOLUTION"), 'Aliare Integra Solution'!$A$9,'Aliare Integra ERP Terceiro'!$A$9) -> Cadastro básico - Unidade de medida | K9: =IF(Resumo!$C$5="ALIARE - SOLUTION", 'Aliare Integra Solution'!$B$9, 'Aliare Integra ERP Terceiro'!$B$9) -> 1.04 Unidade de Medida
D10: x | E10: Safra | F10: Opcional | G10: 0.03125 | J10: =IF(OR(Resumo!$C$5="ALIARE - AGB", Resumo!$C$5="SIMER",Resumo!$C$5="ALIARE - SOLUTION"), 'Aliare Integra Solution'!$A$33,'Aliare Integra ERP Terceiro'!$A$33) -> Cadastro básico - Safra | K10: =IF(Resumo!$C$5="ALIARE - SOLUTION", 'Aliare Integra Solution'!$B$33, 'Aliare Integra ERP Terceiro'!$B$33) -> 1.13 Safra
D11: x | E11: Cultura | F11: Opcional | J11: =IF(OR(Resumo!$C$5="ALIARE - AGB", Resumo!$C$5="SIMER",Resumo!$C$5="ALIARE - SOLUTION"), 'Aliare Integra Solution'!$A$32,'Aliare Integra ERP Terceiro'!$A$32) -> Cadastro básico - Cultura | K11: =IF(Resumo!$C$5="ALIARE - SOLUTION", 'Aliare Integra Solution'!$B$32, 'Aliare Integra ERP Terceiro'!$B$32) -> 1.12 Cultura
E12: Banco/Cooperativa | F12: Opcional | G12: 0.03125
E13: Área de Negócio | F13: Opcional | G13: 0.03125
D14: x | E14: Região | F14: Obrigatório | G14: 0.03125 | J14: =IF(OR(Resumo!$C$5="ALIARE - AGB", Resumo!$C$5="SIMER",Resumo!$C$5="ALIARE - SOLUTION"), _xlfn.CONCAT('Aliare Integra Solution'!$A$34,"+", 'Aliare Integra Solution'!$A$35), _xlfn.CONCAT('Aliare Integra ERP Terceiro'!$A$34,"+",'Aliare Integra ERP Terceiro'!$A$35)) -> Cadastro básico - Região+Cadastro básico - Região local | K14: =IF(Resumo!$C$5="ALIARE - SOLUTION", _xlfn.CONCAT('Aliare Integra Solution'!$B$34,"+", 'Aliare Integra Solution'!$B$35), _xlfn.CONCAT('Aliare Integra ERP Terceiro'!$B$34,"+",'Aliare Integra ERP Terceiro'!$B$35)) -> 1.19 Região+1.20 Região Local
C15: Parceiro | D15: x | E15: Propriedade | F15: Obrigatório | G15: 0.0625 | J15: =IF(OR(Resumo!$C$5="ALIARE - AGB", Resumo!$C$5="SIMER",Resumo!$C$5="ALIARE - SOLUTION"), 'Aliare Integra Solution'!$A$37,'Aliare Integra ERP Terceiro'!$A$37) -> Cadastro básico - Propriedade | K15: =IF(Resumo!$C$5="ALIARE - SOLUTION", 'Aliare Integra Solution'!$B$37, 'Aliare Integra ERP Terceiro'!$B$37) -> 1.22 Propriedade
D16: x | E16: Parceiro / Pessoa Física / Pessoa Jurídica | F16: Obrigatório | G16: 0.03125 | J16: =IF(OR(Resumo!$C$5="ALIARE - AGB", Resumo!$C$5="SIMER",Resumo!$C$5="ALIARE - SOLUTION"), _xlfn.CONCAT('Aliare Integra Solution'!$A$10,'Aliare Integra Solution'!$A$19,'Aliare Integra Solution'!$A$81), _xlfn.CONCAT('Aliare Integra ERP Terceiro'!$A$10,'Aliare Integra ERP Terceiro'!$A$19,'Aliare Integra ERP Terceiro'!$A$83)) -> Cadastro básico - Parceiro - Parte 1Cadastro básico - Pessoa física e jurídica - Fluxo 1Cadastro básico - Pessoa física complementar | K16: =IF(Resumo!$C$5="ALIARE - SOLUTION", 'Aliare Integra Solution'!$B$19, 'Aliare Integra ERP Terceiro'!$B$19) -> 1.16 Pessoa Física e 1.17 Pessoa Jurídica
E17: Times de Futebol | F17: Opcional | G17: 0.03125
E18: Tipos de Restrições do Local do Parceiro | F18: Opcional | G18: 0.03125
D19: x | E19: Contato | F19: Opcional | G19: 0.03125
E20: Cônjuge | F20: Opcional | G20: 0.03125
E21: Tipo parceiro | F21: Opcional | G21: 0.03125
E22: Classificação de Parceiro | F22: Opcional | G22: 0.03125
D23: x | E23: Notas | F23: Obrigatório | G23: 0.03125
D24: x | E24: Parceiro Superior | F24: Opcional | G24: 0.03125
E25: Grupo de Compra | F25: Opcional | G25: 0.041666667
D26: x | E26: Cadastro de Documentos | F26: Opcional | G26: 0.017361111
D27: x | E27: Local | F27: Obrigatório | G27: 0.03125 | I27: =IF(Resumo!$C$5="ALIARE - SOLUTION", 'Aliare Integra Solution'!$AC$12, 'Aliare Integra ERP Terceiro'!$AC$12) -> 0.125 | J27: =IF(OR(Resumo!$C$5="ALIARE - AGB", Resumo!$C$5="SIMER",Resumo!$C$5="ALIARE - SOLUTION"), _xlfn.CONCAT('Aliare Integra Solution'!$A$12,'Aliare Integra Solution'!$A$13,'Aliare Integra Solution'!$A$14), _xlfn.CONCAT('Aliare Integra ERP Terceiro'!$A$12,'Aliare Integra ERP Terceiro'!$A$13,'Aliare Integra ERP Terceiro'!$A$14)) -> Cadastro básico - Local - Entidade EmpresaCadastro básico - Local - Entidade ParceiroCadastro básico - Local - Entidade Propriedade | K27: =IF(Resumo!$C$5="ALIARE - SOLUTION", 'Aliare Integra Solution'!$B$12, 'Aliare Integra ERP Terceiro'!$B$12) -> 1.06 Local
D28: x | E28: Cadastro de Maquinário (Inventário de máquinas) | F28: Obrigatório | G28: 0.041666667
E29: Tipo Prioridade | F29: Opcional
C30: Lead | D30: x | E30: Origem do Lead, Cliente e Oportunidade | F30: Opcional | G30: 0.03125
D31: x | E31: Etapas do Lead | F31: Obrigatório | G31: 0.041666667
D32: x | E32: Tipo de Lead | F32: Opcional | G32: 0.03125
D33: x | E33: Lead | F33: Obrigatório | G33: 0.041666667
E34: Setor do Lead | F34: Opcional | G34: 0.03125
C35: Usuário | D35: x | E35: Usuário x Classe / Classe x Usuário | F35: Opcional | G35: 0.020833333
D36: x | E36: Usuário (Dados Gerais) | F36: Opcional | G36: 0.020833333
D37: x | E37: Empresa | F37: Obrigatório | G37: 0.020833333
D38: x | E38: Parceiro | F38: Obrigatório | G38: 0.020833333 | J38: =IF(OR(Resumo!$C$5="ALIARE - AGB", Resumo!$C$5="SIMER",Resumo!$C$5="ALIARE - SOLUTION"), 'Aliare Integra Solution'!$A$28,'Aliare Integra ERP Terceiro'!$A$28) -> Cadastro básico - Usuário empresa, filial e parceiro | K38: =IF(Resumo!$C$5="ALIARE - SOLUTION", _xlfn.CONCAT('Aliare Integra Solution'!$B$28,"+", 'Aliare Integra Solution'!$B$29), _xlfn.CONCAT('Aliare Integra ERP Terceiro'!$B$29,"+",'Aliare Integra ERP Terceiro'!$B$30)) -> 1.28 Usuário Filial+1.29 Usuário Empresa
D39: x | E39: Filial | F39: Obrigatório | G39: 0.020833333
D40: x | E40: Copiar Dados de Usuário | F40: Obrigatório | G40: 0.020833333
...

Sheet Cálculo do AFV (configuração)
B1: =SUM(B2:B37) -> 43.25
A2: tipo de negociação | B2: 1
A3: configurador de tipo de negociação | B3: 2
A4: Configurador geral de pedido | B4: 0.5
A5: Campanha de troca | B5: 1
A6: Campanha de oferta | B6: 1
A7: Cota | B7: 1.5
A8: Frete | B8: 1.5
A9: Comissão | B9: 1
A10: Avalista | B10: 1
A11: Acompanhamento do pedido; | B11: 2
A12: Limite de crédito | B12: 0.5
A13: Estoque | B13: 1
A14: tipo de documento de cobrança | B14: 0.75
A15: Configuração AFV Manager | C15: 8 | D15: poderá ser reduzido
A16: Cadastro de impostos de troca | B16: 1.5
A17: Configurador de margem | B17: 1
A18: Semáforo | B18: 1.5
A19: Exportação de pedido | B19: 8
A20: Avaliação de máquina usada | B20: 1
A21: Conversor de moedas | B21: 1
A22: Analítico | B22: 1.5
A23: Regra de aprovação de pedido | B23: 3
A24: Cadastro de impostos ICMS | B24: 2
A25: Configuração de usuário | B25: 1
A26: Consulta de preço e estoque | B26: 1.5
A27: Títulos | B27: 0.5
A28: Ordem de Carregamento | B28: 2
A29: Substituição de itens | B29: 2 | D29: não será mais preciso fazer com o Aliare Integra, tendo em vista que esse recurso é permitido fazer no AGB
A30: Preço Exceção | B30: 1

Sheet Aliare Integra Solution
H1: =Resumo!$A15 -> x | I1: =Resumo!$A16 -> 0 | J1: =Resumo!#REF! -> #REF! | K1: =Resumo!#REF! -> #REF! | L1: =Resumo!#REF! -> #REF! | M1: =Resumo!A17 -> 0 | N1: =Resumo!A18 -> 0 | O1: =Resumo!A19 -> 0 | P1: =Resumo!#REF! -> #REF! | Q1: =Resumo!A20 -> 0 | R1: =Resumo!#REF! -> #REF! | S1: =Resumo!A21 -> 0 | T1: =Resumo!A22 -> 0 | U1: =Resumo!#REF! -> #REF! | V1: =Resumo!A23 -> x | W1: =Resumo!A24 -> 0 | X1: =Resumo!A25 -> 0 | Y1: =Resumo!#REF! -> #REF! | Z1: =Resumo!A26 -> 0 | AA1: =Resumo!A27 -> 0 | AB1: =Resumo!#REF! -> #REF!
A2: Fluxos | B2: Tabela | C2: Tipo | D2: Cofig. Integração AGB | E2: Teste interno, carga inicial | F2: Apoio a Validação / homologação e produção AGB | G2: Validação / homologação AGB | H2: CRM - MM - Funcionalidades Fundamentais | I2: CRM - MM - Registro de Visita | J2: CRM - MM - Planejamento da Consultoria Agronômica | K2: CRM - MM - Campos Demonstrativos | L2: CRM - MM - Consulta Preço e Estoque à Campo | M2: CRM - MM - Potencial & Metas | N2: CRM - MM - Segmentação | O2: CRM - MM - Previsão de Vendas | P2: CRM - MM - MarketShare | Q2: CRM - MM - Analise de Vendas | R2: CRM - MM - Escoamento de produtos | S2: CRM - MM - Potencial Maquinas | T2: CRM - MM - Chamados | U2: CRM - MM - Questionário de Pós Venda | V2: CRM - MM - Força de Vendas | W2: CRM - MM - Viagem | X2: CRM - MM - Funil de Vendas | Y2: CRM - MM - Levantamento de Rebanho | Z2: CRM - MM - Proposta de Crédito | AA2: CRM - MM - Ordem de Serviço | AB2: CRM - MM - Gestão de Eventos | AC2: Aliare Integra | AD2: CeS
B3: Todos os cadastros básicos | C3: **Sempre | D3: 0 | H3: SIM | I3: SIM | J3: SIM | K3: SIM | L3: SIM | M3: SIM | N3: SIM | O3: SIM | P3: SIM | Q3: SIM | R3: SIM | S3: SIM | T3: SIM | U3: SIM | V3: SIM | W3: SIM | X3: SIM | Y3: SIM | Z3: SIM | AA3: SIM | AB3: SIM | AC3: =IF(COUNTIFS($H$1:$AB$1,"x",H3:AB3,"SIM")>0,(D3+E3+F3),0) -> 0 | AD3: =IF(COUNTIFS($H$1:$AB$1,"x",H3:AB3,"SIM")>0,G3,0) -> 0 | AE3: =COUNTIFS(H3:AB3,"SIM") -> 21
B4: Todas as movimentações financeiras | C4: **Sempre | D4: 0 | H4: SIM | I4: SIM | J4: SIM | K4: SIM | L4: SIM | M4: SIM | N4: SIM | O4: SIM | P4: SIM | Q4: SIM | R4: SIM | S4: SIM | T4: SIM | U4: SIM | V4: SIM | W4: SIM | X4: SIM | Y4: SIM | Z4: SIM | AA4: SIM | AB4: SIM | AC4: =IF(COUNTIFS($H$1:$AB$1,"x",H4:AB4,"SIM")>0,(D4+E4+F4),0) -> 0 | AD4: =IF(COUNTIFS($H$1:$AB$1,"x",H4:AB4,"SIM")>0,G4,0) -> 0 | AE4: =COUNTIFS(H4:AB4,"SIM") -> 21
B5: Todos os fluxos de força de venda | C5: **Sempre | D5: 0 | H5: SIM | I5: SIM | J5: SIM | K5: SIM | L5: SIM | M5: SIM | N5: SIM | O5: SIM | P5: SIM | Q5: SIM | R5: SIM | S5: SIM | T5: SIM | U5: SIM | V5: SIM | W5: SIM | X5: SIM | Y5: SIM | Z5: SIM | AA5: SIM | AB5: SIM | AC5: =IF(COUNTIFS($H$1:$AB$1,"x",H5:AB5,"SIM")>0,(D5+E5+F5),0) -> 0 | AD5: =IF(COUNTIFS($H$1:$AB$1,"x",H5:AB5,"SIM")>0,G5,0) -> 0 | AE5: =COUNTIFS(H5:AB5,"SIM") -> 21
A6: Cadastro básico - País, Estado e Cidade | B6: 1.01 País | C6: **Sempre | D6: 0.0069444444 | E6: 0.020833333 | F6: 0 | G6: 0.020833333 | H6: SIM | I6: SIM | J6: SIM | K6: SIM | L6: SIM | M6: SIM | N6: SIM | O6: SIM | P6: SIM | Q6: SIM | R6: SIM | S6: SIM | T6: SIM | U6: SIM | V6: SIM | W6: SIM | X6: SIM | Y6: SIM | Z6: SIM | AA6: SIM | AB6: SIM | AC6: =IF(COUNTIFS($H$1:$AB$1,"x",H6:AB6,"SIM")>0,(D6+E6+F6),0) -> 0.027777778 | AD6: =IF(COUNTIFS($H$1:$AB$1,"x",H6:AB6,"SIM")>0,G6,0) -> 0.020833333 | AE6: =COUNTIFS(H6:AB6,"SIM") -> 21
B7: 1.02 Unidade Federativa | C7: **Sempre | H7: SIM | I7: SIM | J7: SIM | K7: SIM | L7: SIM | M7: SIM | N7: SIM | O7: SIM | P7: SIM | Q7: SIM | R7: SIM | S7: SIM | T7: SIM | U7: SIM | V7: SIM | W7: SIM | X7: SIM | Y7: SIM | Z7: SIM | AA7: SIM | AB7: SIM | AC7: =IF(COUNTIFS($H$1:$AB$1,"x",H7:AB7,"SIM")>0,(D7+E7+F7),0) -> 0 | AD7: =IF(COUNTIFS($H$1:$AB$1,"x",H7:AB7,"SIM")>0,G7,0) -> 0 | AE7: =COUNTIFS(H7:AB7,"SIM") -> 21
B8: 1.03 Cidade | C8: **Sempre | H8: SIM | I8: SIM | J8: SIM | K8: SIM | L8: SIM | M8: SIM | N8: SIM | O8: SIM | P8: SIM | Q8: SIM | R8: SIM | S8: SIM | T8: SIM | U8: SIM | V8: SIM | W8: SIM | X8: SIM | Y8: SIM | Z8: SIM | AA8: SIM | AB8: SIM | AC8: =IF(COUNTIFS($H$1:$AB$1,"x",H8:AB8,"SIM")>0,(D8+E8+F8),0) -> 0 | AD8: =IF(COUNTIFS($H$1:$AB$1,"x",H8:AB8,"SIM")>0,G8,0) -> 0 | AE8: =COUNTIFS(H8:AB8,"SIM") -> 21
A9: Cadastro básico - Unidade de medida | B9: 1.04 Unidade de Medida | C9: **Sempre | D9: 0.0069444444 | E9: 0.0069444444 | F9: 0 | G9: 0.010416667 | H9: SIM | I9: SIM | J9: SIM | K9: SIM | L9: SIM | M9: SIM | N9: SIM | O9: SIM | P9: SIM | Q9: SIM | R9: SIM | S9: SIM | T9: SIM | U9: SIM | V9: SIM | W9: SIM | X9: SIM | Y9: SIM | Z9: SIM | AA9: SIM | AB9: SIM | AC9: =IF(COUNTIFS($H$1:$AB$1,"x",H9:AB9,"SIM")>0,(D9+E9+F9),0) -> 0.013888889 | AD9: =IF(COUNTIFS($H$1:$AB$1,"x",H9:AB9,"SIM")>0,G9,0) -> 0.010416667 | AE9: =COUNTIFS(H9:AB9,"SIM") -> 21
A10: Cadastro básico - Parceiro - Parte 1 | B10: 1.05 Parceiro | C10: **Sempre | D10: 0.09375 | E10: 0.020833333 | F10: 0.020833333 | G10: 0.020833333 | H10: SIM | I10: SIM | J10: SIM | K10: SIM | L10: SIM | M10: SIM | N10: SIM | O10: SIM | P10: SIM | Q10: SIM | R10: SIM | S10: SIM | T10: SIM | U10: SIM | V10: SIM | W10: SIM | X10: SIM | Y10: SIM | Z10: SIM | AA10: SIM | AB10: SIM | AC10: =IF(COUNTIFS($H$1:$AB$1,"x",H10:AB10,"SIM")>0,(D10+E10+F10),0) -> 0.13541667 | AD10: =IF(COUNTIFS($H$1:$AB$1,"x",H10:AB10,"SIM")>0,G10,0) -> 0.020833333 | AE10: =COUNTIFS(H10:AB10,"SIM") -> 21
A11: Cadastro básico - Parceiro - Parte 2 | H11: SIM | I11: SIM | J11: SIM | K11: SIM | L11: SIM | M11: SIM | N11: SIM | O11: SIM | P11: SIM | Q11: SIM | R11: SIM | S11: SIM | T11: SIM | U11: SIM | V11: SIM | W11: SIM | X11: SIM | Y11: SIM | Z11: SIM | AA11: SIM | AB11: SIM | AC11: =IF(COUNTIFS($H$1:$AB$1,"x",H11:AB11,"SIM")>0,(D11+E11+F11),0) -> 0 | AD11: =IF(COUNTIFS($H$1:$AB$1,"x",H11:AB11,"SIM")>0,G11,0) -> 0 | AE11: =COUNTIFS(H11:AB11,"SIM") -> 21
A12: Cadastro básico - Local - Entidade Empresa | B12: 1.06 Local | C12: **Sempre | D12: 0.125 | E12: 0 | F12: 0 | G12: 0.020833333 | H12: SIM | I12: SIM | J12: SIM | K12: SIM | L12: SIM | M12: SIM | N12: SIM | O12: SIM | P12: SIM | Q12: SIM | R12: SIM | S12: SIM | T12: SIM | U12: SIM | V12: SIM | W12: SIM | X12: SIM | Y12: SIM | Z12: SIM | AA12: SIM | AB12: SIM | AC12: =IF(COUNTIFS($H$1:$AB$1,"x",H12:AB12,"SIM")>0,(D12+E12+F12),0) -> 0.125 | AD12: =IF(COUNTIFS($H$1:$AB$1,"x",H12:AB12,"SIM")>0,G12,0) -> 0.020833333 | AE12: =COUNTIFS(H12:AB12,"SIM") -> 21
A13: Cadastro básico - Local - Entidade Parceiro | H13: SIM | I13: SIM | J13: SIM | K13: SIM | L13: SIM | M13: SIM | N13: SIM | O13: SIM | P13: SIM | Q13: SIM | R13: SIM | S13: SIM | T13: SIM | U13: SIM | V13: SIM | W13: SIM | X13: SIM | Y13: SIM | Z13: SIM | AA13: SIM | AB13: SIM | AC13: =IF(COUNTIFS($H$1:$AB$1,"x",H13:AB13,"SIM")>0,(D13+E13+F13),0) -> 0 | AD13: =IF(COUNTIFS($H$1:$AB$1,"x",H13:AB13,"SIM")>0,G13,0) -> 0 | AE13: =COUNTIFS(H13:AB13,"SIM") -> 21
A14: Cadastro básico - Local - Entidade Propriedade | H14: SIM | I14: SIM | J14: SIM | K14: SIM | L14: SIM | M14: SIM | N14: SIM | O14: SIM | P14: SIM | Q14: SIM | R14: SIM | S14: SIM | T14: SIM | U14: SIM | V14: SIM | W14: SIM | X14: SIM | Y14: SIM | Z14: SIM | AA14: SIM | AB14: SIM | AC14: =IF(COUNTIFS($H$1:$AB$1,"x",H14:AB14,"SIM")>0,(D14+E14+F14),0) -> 0 | AD14: =IF(COUNTIFS($H$1:$AB$1,"x",H14:AB14,"SIM")>0,G14,0) -> 0 | AE14: =COUNTIFS(H14:AB14,"SIM") -> 21
A15: Cadastro básico – Empresa | B15: 1.14 Empresa | C15: **Sempre | D15: 0.0069444444 | E15: 0.0069444444 | F15: 0 | G15: 0.010416667 | H15: SIM | I15: SIM | J15: SIM | K15: SIM | L15: SIM | M15: SIM | N15: SIM | O15: SIM | P15: SIM | Q15: SIM | R15: SIM | S15: SIM | T15: SIM | U15: SIM | V15: SIM | W15: SIM | X15: SIM | Y15: SIM | Z15: SIM | AA15: SIM | AB15: SIM | AC15: =IF(COUNTIFS($H$1:$AB$1,"x",H15:AB15,"SIM")>0,(D15+E15+F15),0) -> 0.013888889 | AD15: =IF(COUNTIFS($H$1:$AB$1,"x",H15:AB15,"SIM")>0,G15,0) -> 0.010416667 | AE15: =COUNTIFS(H15:AB15,"SIM") -> 21
A16: Cadastro básico - Registrante | B16: 1.15.1 Registrante / Fabricante | C16: *Módulo | D16: 0.0069444444 | E16: 0.0069444444 | F16: 0.0069444444 | H16: NÃO | I16: SIM | J16: SIM | K16: SIM | L16: SIM | M16: SIM | N16: SIM | O16: SIM | P16: SIM | Q16: SIM | R16: SIM | S16: SIM | T16: SIM | U16: SIM | V16: SIM | W16: SIM | X16: SIM | Y16: SIM | Z16: SIM | AA16: SIM | AB16: SIM | AC16: =IF(COUNTIFS($H$1:$AB$1,"x",H16:AB16,"SIM")>0,(D16+E16+F16),0) -> 0.020833333 | AD16: =IF(COUNTIFS($H$1:$AB$1,"x",H16:AB16,"SIM")>0,G16,0) -> 0 | AE16: =COUNTIFS(H16:AB16,"SIM") -> 20
A17: Cadastro básico - Fornecedor | B17: 1.15.2 Fornecedor | C17: *Módulo | D17: 0.0069444444 | E17: 0.0069444444 | F17: 0.0069444444 | H17: NÃO | I17: SIM | J17: SIM | K17: SIM | L17: SIM | M17: SIM | N17: SIM | O17: SIM | P17: SIM | Q17: SIM | R17: SIM | S17: SIM | T17: SIM | U17: SIM | V17: SIM | W17: SIM | X17: SIM | Y17: SIM | Z17: SIM | AA17: SIM | AB17: SIM | AC17: =IF(COUNTIFS($H$1:$AB$1,"x",H17:AB17,"SIM")>0,(D17+E17+F17),0) -> 0.020833333 | AD17: =IF(COUNTIFS($H$1:$AB$1,"x",H17:AB17,"SIM")>0,G17,0) -> 0 | AE17: =COUNTIFS(H17:AB17,"SIM") -> 20
A18: Cadastro básico - Filial | B18: 1.15 Filial | C18: **Sempre | D18: 0.0069444444 | E18: 0.0069444444 | F18: 0.0069444444 | G18: 0.017361111 | H18: SIM | I18: SIM | J18: SIM | K18: SIM | L18: SIM | M18: SIM | N18: SIM | O18: SIM | P18: SIM | Q18: SIM | R18: SIM | S18: SIM | T18: SIM | U18: SIM | V18: SIM | W18: SIM | X18: SIM | Y18: SIM | Z18: SIM | AA18: SIM | AB18: SIM | AC18: =IF(COUNTIFS($H$1:$AB$1,"x",H18:AB18,"SIM")>0,(D18+E18+F18),0) -> 0.020833333 | AD18: =IF(COUNTIFS($H$1:$AB$1,"x",H18:AB18,"SIM")>0,G18,0) -> 0.017361111 | AE18: =COUNTIFS(H18:AB18,"SIM") -> 21
A19: Cadastro básico - Pessoa física e jurídica - Fluxo 1 | B19: 1.16 Pessoa Física e 1.17 Pessoa Jurídica | C19: **Sempre | D19: 0.013888889 | E19: 0.020833333 | F19: 0.027777778 | G19: 0.041666667 | H19: SIM | I19: SIM | J19: SIM | K19: SIM | L19: SIM | M19: SIM | N19: SIM | O19: SIM | P19: SIM | Q19: SIM | R19: SIM | S19: SIM | T19: SIM | U19: SIM | V19: SIM | W19: SIM | X19: SIM | Y19: SIM | Z19: SIM | AA19: SIM | AB19: SIM | AC19: =IF(COUNTIFS($H$1:$AB$1,"x",H19:AB19,"SIM")>0,(D19+E19+F19),0) -> 0.0625 | AD19: =IF(COUNTIFS($H$1:$AB$1,"x",H19:AB19,"SIM")>0,G19,0) -> 0.041666667 | AE19: =COUNTIFS(H19:AB19,"SIM") -> 21
A20: Cadastro básico - Pessoa física - Fluxo 2 | H20: SIM | I20: SIM | J20: SIM | K20: SIM | L20: SIM | M20: SIM | N20: SIM | O20: SIM | P20: SIM | Q20: SIM | R20: SIM | S20: SIM | T20: SIM | U20: SIM | V20: SIM | W20: SIM | X20: SIM | Y20: SIM | Z20: SIM | AA20: SIM | AB20: SIM | AC20: =IF(COUNTIFS($H$1:$AB$1,"x",H20:AB20,"SIM")>0,(D20+E20+F20),0) -> 0 | AD20: =IF(COUNTIFS($H$1:$AB$1,"x",H20:AB20,"SIM")>0,G20,0) -> 0 | AE20: =COUNTIFS(H20:AB20,"SIM") -> 21
A21: Cadastro básico - Pessoa jurídica - Fluxo 3 | AC21: =IF(COUNTIFS($H$1:$AB$1,"x",H21:AB21,"SIM")>0,(D21+E21+F21),0) -> 0 | AD21: =IF(COUNTIFS($H$1:$AB$1,"x",H21:AB21,"SIM")>0,G21,0) -> 0 | AE21: =COUNTIFS(H21:AB21,"SIM") -> 0
A22: Cadastro básico - Produto e produto classe | B22: 1.08 Produto e 1.10 Produto Classe | C22: *Módulo | D22: 0.125 | E22: 0 | F22: 0 | G22: 0.013888889 | H22: SIM | I22: SIM | J22: SIM | K22: SIM | L22: SIM | M22: SIM | N22: SIM | O22: SIM | P22: SIM | Q22: SIM | R22: SIM | S22: SIM | T22: SIM | U22: SIM | V22: SIM | W22: SIM | X22: SIM | Y22: SIM | Z22: SIM | AA22: SIM | AB22: SIM | AC22: =IF(COUNTIFS($H$1:$AB$1,"x",H22:AB22,"SIM")>0,(D22+E22+F22),0) -> 0.125 | AD22: =IF(COUNTIFS($H$1:$AB$1,"x",H22:AB22,"SIM")>0,G22,0) -> 0.013888889 | AE22: =COUNTIFS(H22:AB22,"SIM") -> 21
A23: Cadastro básico - Classe de produto | B23: 1.09 Classe de Produto | C23: *Módulo | D23: 0.0069444444 | E23: 0.017361111 | F23: 0.017361111 | G23: 0.013888889 | H23: NÃO | I23: SIM | J23: SIM | K23: SIM | L23: SIM | M23: SIM | N23: SIM | O23: SIM | P23: SIM | Q23: SIM | R23: SIM | S23: SIM | T23: SIM | U23: SIM | V23: SIM | W23: SIM | X23: SIM | Y23: SIM | Z23: SIM | AA23: SIM | AB23: SIM | AC23: =IF(COUNTIFS($H$1:$AB$1,"x",H23:AB23,"SIM")>0,(D23+E23+F23),0) -> 0.041666667 | AD23: =IF(COUNTIFS($H$1:$AB$1,"x",H23:AB23,"SIM")>0,G23,0) -> 0.013888889 | AE23: =COUNTIFS(H23:AB23,"SIM") -> 20
A24: Movimentação financeira - Local nota fiscal | B24: 3.1 Local Nota Fiscal | C24: *Módulo | D24: 0.45833333 | E24: 0 | F24: 0 | G24: 0.083333333 | H24: NÃO | I24: SIM | J24: NÃO | K24: NÃO | L24: NÃO | M24: SIM | N24: NÃO | O24: SIM | P24: SIM | Q24: SIM | R24: SIM | S24: NÃO | T24: NÃO | U24: SIM | V24: NÃO | W24: NÃO | X24: SIM | Y24: NÃO | Z24: NÃO | AA24: NÃO | AB24: NÃO | AC24: =IF(COUNTIFS($H$1:$AB$1,"x",H24:AB24,"SIM")>0,(D24+E24+F24),0) -> 0 | AD24: =IF(COUNTIFS($H$1:$AB$1,"x",H24:AB24,"SIM")>0,G24,0) -> 0 | AE24: =COUNTIFS(H24:AB24,"SIM") -> 8
A25: Movimentação financeira - Faturamento mensal - Parte 1 | B25: 3.2 Pedidos em Carteira (Fat. Mensal) | C25: *Módulo | D25: 0 | E25: 0 | F25: 0 | G25: 0.16666667 | H25: NÃO | I25: NÃO | J25: NÃO | K25: NÃO | L25: NÃO | M25: SIM | N25: SIM | O25: SIM | P25: NÃO | Q25: SIM | R25: NÃO | S25: NÃO | T25: NÃO | U25: NÃO | V25: NÃO | W25: NÃO | X25: NÃO | Y25: NÃO | Z25: NÃO | AA25: NÃO | AB25: NÃO | AC25: =IF(COUNTIFS($H$1:$AB$1,"x",H25:AB25,"SIM")>0,(D25+E25+F25),0) -> 0 | AD25: =IF(COUNTIFS($H$1:$AB$1,"x",H25:AB25,"SIM")>0,G25,0) -> 0 | AE25: =COUNTIFS(H25:AB25,"SIM") -> 4
A26: Movimentação financeira - Faturamento mensal - Parte 2 | AC26: =IF(COUNTIFS($H$1:$AB$1,"x",H26:AB26,"SIM")>0,(D26+E26+F26),0) -> 0 | AD26: =IF(COUNTIFS($H$1:$AB$1,"x",H26:AB26,"SIM")>0,G26,0) -> 0 | AE26: =COUNTIFS(H26:AB26,"SIM") -> 0
A27: Cadastro básico - Usuários | B27: 1.11 Usuário | C27: *Qualifica | D27: 0.0069444444 | E27: 0.0069444444 | F27: 0 | G27: 0.0069444444 | H27: SIM | I27: SIM | J27: NÃO | K27: NÃO | L27: SIM | M27: NÃO | N27: NÃO | O27: NÃO | P27: NÃO | Q27: NÃO | R27: NÃO | S27: NÃO | T27: NÃO | U27: NÃO | V27: SIM | W27: NÃO | X27: NÃO | Y27: NÃO | Z27: NÃO | AA27: NÃO | AB27: NÃO | AC27: =IF(COUNTIFS($H$1:$AB$1,"x",H27:AB27,"SIM")>0,(D27+E27+F27),0) -> 0.013888889 | AD27: =IF(COUNTIFS($H$1:$AB$1,"x",H27:AB27,"SIM")>0,G27,0) -> 0.0069444444 | AE27: =COUNTIFS(H27:AB27,"SIM") -> 4
A28: Cadastro básico - Usuário empresa, filial e parceiro | B28: 1.28 Usuário Filial | C28: *Qualifica | D28: 0.010416667 | E28: 0.010416667 | F28: 0.0069444444 | G28: 0.020833333 | H28: SIM | I28: =$H$27 -> SIM | J28: NÃO | K28: NÃO | L28: SIM | M28: NÃO | N28: NÃO | O28: NÃO | P28: NÃO | Q28: NÃO | R28: NÃO | S28: NÃO | T28: NÃO | U28: NÃO | V28: SIM | W28: NÃO | X28: NÃO | Y28: NÃO | Z28: NÃO | AA28: NÃO | AB28: NÃO | AC28: =IF(COUNTIFS($H$1:$AB$1,"x",H28:AB28,"SIM")>0,(D28+E28+F28),0) -> 0.027777778 | AD28: =IF(COUNTIFS($H$1:$AB$1,"x",H28:AB28,"SIM")>0,G28,0) -> 0.020833333 | AE28: =COUNTIFS(H28:AB28,"SIM") -> 4
B29: 1.29 Usuário Empresa | C29: *Qualifica | H29: SIM | I29: =$H$27 -> SIM | J29: NÃO | K29: NÃO | L29: SIM | M29: NÃO | N29: NÃO | O29: NÃO | P29: NÃO | Q29: NÃO | R29: NÃO | S29: NÃO | T29: NÃO | U29: NÃO | V29: SIM | W29: NÃO | X29: NÃO | Y29: NÃO | Z29: NÃO | AA29: NÃO | AB29: NÃO | AC29: =IF(COUNTIFS($H$1:$AB$1,"x",H29:AB29,"SIM")>0,(D29+E29+F29),0) -> 0 | AD29: =IF(COUNTIFS($H$1:$AB$1,"x",H29:AB29,"SIM")>0,G29,0) -> 0 | AE29: =COUNTIFS(H29:AB29,"SIM") -> 4
B30: 1.28 Usuário Parceiro | C30: *Qualifica | H30: SIM | I30: =$H$27 -> SIM | J30: NÃO | K30: NÃO | L30: SIM | M30: NÃO | N30: NÃO | O30: NÃO | P30: NÃO | Q30: NÃO | R30: NÃO | S30: NÃO | T30: NÃO | U30: NÃO | V30: SIM | W30: NÃO | X30: NÃO | Y30: NÃO | Z30: NÃO | AA30: NÃO | AB30: NÃO | AC30: =IF(COUNTIFS($H$1:$AB$1,"x",H30:AB30,"SIM")>0,(D30+E30+F30),0) -> 0 | AD30: =IF(COUNTIFS($H$1:$AB$1,"x",H30:AB30,"SIM")>0,G30,0) -> 0 | AE30: =COUNTIFS(H30:AB30,"SIM") -> 4
B31: 1.27 Usuário Produto | C31: *Qualifica | H31: NÃO | I31: NÃO | J31: NÃO | K31: NÃO | L31: NÃO | M31: NÃO | N31: NÃO | O31: NÃO | P31: NÃO | Q31: NÃO | R31: NÃO | S31: NÃO | T31: NÃO | U31: NÃO | V31: NÃO | W31: NÃO | X31: NÃO | Y31: NÃO | Z31: NÃO | AA31: NÃO | AB31: NÃO | AC31: =IF(COUNTIFS($H$1:$AB$1,"x",H31:AB31,"SIM")>0,(D31+E31+F31),0) -> 0 | AD31: =IF(COUNTIFS($H$1:$AB$1,"x",H31:AB31,"SIM")>0,G31,0) -> 0 | AE31: =COUNTIFS(H31:AB31,"SIM") -> 0
A32: Cadastro básico - Cultura | B32: 1.12 Cultura | C32: *Qualifica | D32: 0.0069444444 | E32: 0.0069444444 | F32: 0 | G32: 0.0069444444 | H32: SIM | I32: SIM | J32: SIM | K32: SIM | L32: SIM | M32: SIM | N32: NÃO | O32: NÃO | P32: NÃO | Q32: NÃO | R32: NÃO | S32: NÃO | T32: NÃO | U32: NÃO | V32: SIM | W32: NÃO | X32: NÃO | Y32: NÃO | Z32: NÃO | AA32: NÃO | AB32: NÃO | AC32: =IF(COUNTIFS($H$1:$AB$1,"x",H32:AB32,"SIM")>0,(D32+E32+F32),0) -> 0.013888889 | AD32: =IF(COUNTIFS($H$1:$AB$1,"x",H32:AB32,"SIM")>0,G32,0) -> 0.0069444444 | AE32: =COUNTIFS(H32:AB32,"SIM") -> 7
A33: Cadastro básico - Safra | B33: 1.13 Safra | C33: *Qualifica | D33: 0.0069444444 | E33: 0.0069444444 | F33: 0 | G33: 0.0069444444 | H33: NÃO | I33: SIM | J33: SIM | K33: SIM | L33: SIM | M33: SIM | N33: NÃO | O33: NÃO | P33: NÃO | Q33: SIM | R33: NÃO | S33: NÃO | T33: NÃO | U33: NÃO | V33: SIM | W33: NÃO | X33: NÃO | Y33: NÃO | Z33: NÃO | AA33: NÃO | AB33: NÃO | AC33: =IF(COUNTIFS($H$1:$AB$1,"x",H33:AB33,"SIM")>0,(D33+E33+F33),0) -> 0.013888889 | AD33: =IF(COUNTIFS($H$1:$AB$1,"x",H33:AB33,"SIM")>0,G33,0) -> 0.0069444444 | AE33: =COUNTIFS(H33:AB33,"SIM") -> 7
A34: Cadastro básico - Região | B34: 1.19 Região | C34: *Qualifica | D34: 0.0069444444 | E34: 0.0069444444 | F34: 0 | G34: 0.0069444444 | H34: SIM | I34: SIM | J34: SIM | K34: SIM | L34: SIM | M34: SIM | N34: NÃO | O34: NÃO | P34: NÃO | Q34: NÃO | R34: NÃO | S34: NÃO | T34: NÃO | U34: NÃO | V34: SIM | W34: NÃO | X34: NÃO | Y34: NÃO | Z34: NÃO | AA34: NÃO | AB34: NÃO | AC34: =IF(COUNTIFS($H$1:$AB$1,"x",H34:AB34,"SIM")>0,(D34+E34+F34),0) -> 0.013888889 | AD34: =IF(COUNTIFS($H$1:$AB$1,"x",H34:AB34,"SIM")>0,G34,0) -> 0.0069444444 | AE34: =COUNTIFS(H34:AB34,"SIM") -> 7
A35: Cadastro básico - Região local | B35: 1.20 Região Local | C35: *Qualifica | D35: 0.0069444444 | E35: 0.0069444444 | F35: 0.0069444444 | G35: 0.0069444444 | H35: SIM | I35: SIM | J35: SIM | K35: SIM | L35: SIM | M35: SIM | N35: NÃO | O35: NÃO | P35: NÃO | Q35: NÃO | R35: NÃO | S35: NÃO | T35: NÃO | U35: NÃO | V35: SIM | W35: NÃO | X35: NÃO | Y35: NÃO | Z35: NÃO | AA35: NÃO | AB35: NÃO | AC35: =IF(COUNTIFS($H$1:$AB$1,"x",H35:AB35,"SIM")>0,(D35+E35+F35),0) -> 0.020833333 | AD35: =IF(COUNTIFS($H$1:$AB$1,"x",H35:AB35,"SIM")>0,G35,0) -> 0.0069444444 | AE35: =COUNTIFS(H35:AB35,"SIM") -> 7
A36: Cadastro básico - Usuário região | B36: 1.21 Usuário Região | C36: *Qualifica | D36: 0.0069444444 | E36: 0.0069444444 | F36: 0.0069444444 | G36: 0.0034722222 | H36: SIM | I36: SIM | J36: SIM | K36: SIM | L36: SIM | M36: SIM | N36: NÃO | O36: NÃO | P36: NÃO | Q36: NÃO | R36: NÃO | S36: NÃO | T36: NÃO | U36: NÃO | V36: SIM | W36: NÃO | X36: NÃO | Y36: NÃO | Z36: NÃO | AA36: NÃO | AB36: NÃO | AC36: =IF(COUNTIFS($H$1:$AB$1,"x",H36:AB36,"SIM")>0,(D36+E36+F36),0) -> 0.020833333 | AD36: =IF(COUNTIFS($H$1:$AB$1,"x",H36:AB36,"SIM")>0,G36,0) -> 0.0034722222 | AE36: =COUNTIFS(H36:AB36,"SIM") -> 7
A37: Cadastro básico - Propriedade | B37: 1.22 Propriedade | C37: *Qualifica | D37: 0.013888889 | E37: 0.013888889 | F37: 0 | G37: 0.020833333 | H37: SIM | I37: SIM | J37: SIM | K37: SIM | L37: NÃO | M37: SIM | N37: NÃO | O37: NÃO | P37: NÃO | Q37: NÃO | R37: NÃO | S37: NÃO | T37: NÃO | U37: NÃO | V37: NÃO | W37: NÃO | X37: NÃO | Y37: NÃO | Z37: NÃO | AA37: NÃO | AB37: NÃO | AC37: =IF(COUNTIFS($H$1:$AB$1,"x",H37:AB37,"SIM")>0,(D37+E37+F37),0) -> 0.027777778 | AD37: =IF(COUNTIFS($H$1:$AB$1,"x",H37:AB37,"SIM")>0,G37,0) -> 0.020833333 | AE37: =COUNTIFS(H37:AB37,"SIM") -> 5
A38: Cadastro básico - Vínculo imobiliário | B38: 1.23 Vin. Imob. | C38: *Qualifica | H38: SIM | I38: SIM | J38: SIM | K38: SIM | L38: NÃO | M38: SIM | N38: NÃO | O38: NÃO | P38: NÃO | Q38: NÃO | R38: NÃO | S38: NÃO | T38: NÃO | U38: NÃO | V38: NÃO | W38: NÃO | X38: NÃO | Y38: NÃO | Z38: NÃO | AA38: NÃO | AB38: NÃO | AC38: =IF(COUNTIFS($H$1:$AB$1,"x",H38:AB38,"SIM")>0,(D38+E38+F38),0) -> 0 | AD38: =IF(COUNTIFS($H$1:$AB$1,"x",H38:AB38,"SIM")>0,G38,0) -> 0 | AE38: =COUNTIFS(H38:AB38,"SIM") -> 5
A39: Cadastro básico - Posse | B39: 1.24 Posse | C39: *Qualifica | H39: SIM | I39: SIM | J39: SIM | K39: SIM | L39: NÃO | M39: SIM | N39: NÃO | O39: NÃO | P39: NÃO | Q39: NÃO | R39: NÃO | S39: NÃO | T39: NÃO | U39: NÃO | V39: NÃO | W39: NÃO | X39: NÃO | Y39: NÃO | Z39: NÃO | AA39: NÃO | AB39: NÃO | AC39: =IF(COUNTIFS($H$1:$AB$1,"x",H39:AB39,"SIM")>0,(D39+E39+F39),0) -> 0 | AD39: =IF(COUNTIFS($H$1:$AB$1,"x",H39:AB39,"SIM")>0,G39,0) -> 0 | AE39: =COUNTIFS(H39:AB39,"SIM") -> 5
A40: Cadastro básico - Arrendamento | B40: 1.25 Arrend. | C40: *Qualifica | H40: NÃO | I40: NÃO | J40: NÃO | K40: NÃO | L40: NÃO | M40: NÃO | N40: NÃO | O40: NÃO | P40: NÃO | Q40: NÃO | R40: NÃO | S40: NÃO | T40: NÃO | U40: NÃO | V40: NÃO | W40: NÃO | X40: NÃO | Y40: NÃO | Z40: NÃO | AA40: NÃO | AB40: NÃO | AC40: =IF(COUNTIFS($H$1:$AB$1,"x",H40:AB40,"SIM")>0,(D40+E40+F40),0) -> 0 | AD40: =IF(COUNTIFS($H$1:$AB$1,"x",H40:AB40,"SIM")>0,G40,0) -> 0 | AE40: =COUNTIFS(H40:AB40,"SIM") -> 0
...

Sheet Aliare Integra ERP Terceiro
H1: =Resumo!$A15 -> x | I1: =Resumo!$A16 -> 0 | J1: =Resumo!#REF! -> #REF! | K1: =Resumo!#REF! -> #REF! | L1: =Resumo!#REF! -> #REF! | M1: =Resumo!A17 -> 0 | N1: =Resumo!A18 -> 0 | O1: =Resumo!A19 -> 0 | P1: =Resumo!#REF! -> #REF! | Q1: =Resumo!A20 -> 0 | R1: =Resumo!#REF! -> #REF! | S1: =Resumo!A21 -> 0 | T1: =Resumo!A22 -> 0 | U1: =Resumo!#REF! -> #REF! | V1: =Resumo!A23 -> x | W1: =Resumo!A24 -> 0 | X1: =Resumo!A25 -> 0 | Y1: =Resumo!#REF! -> #REF! | Z1: =Resumo!A26 -> 0 | AA1: =Resumo!A27 -> 0 | AB1: =Resumo!#REF! -> #REF!
A2: Fluxos | B2: Tabela | C2: Tipo | D2: Cofig. Integração ERP Terceiro | E2: Teste interno, carga inicial | F2: Apoio a Validação / homologação e produção ERP Terceiro | G2: Validação de Dados Integrados ERP Terceiro | H2: CRM - MM - Funcionalidades Fundamentais | I2: CRM - MM - Registro de Visita | J2: CRM - MM - Planejamento da Consultoria Agronômica | K2: CRM - MM - Campos Demonstrativos | L2: CRM - MM - Consulta Preço e Estoque à Campo | M2: CRM - MM - Potencial & Metas | N2: CRM - MM - Segmentação | O2: CRM - MM - Previsão de Vendas | P2: CRM - MM - MarketShare | Q2: CRM - MM - Analise de Vendas | R2: CRM - MM - Escoamento de produtos | S2: CRM - MM - Potencial Maquinas | T2: CRM - MM - Chamados | U2: CRM - MM - Questionário de Pós Venda | V2: CRM - MM - Força de Vendas | W2: CRM - MM - Viagem | X2: CRM - MM - Funil de Vendas | Y2: CRM - MM - Levantamento de Rebanho | Z2: CRM - MM - Proposta de Crédito | AA2: CRM - MM - Ordem de Serviço | AB2: CRM - MM - Gestão de Eventos | AC2: Aliare Integra | AD2: CeS
B3: Todos os cadastros básicos | C3: **Sempre | D3: 0 | F3: 0 | G3: 0 | H3: SIM | I3: SIM | J3: SIM | K3: SIM | L3: SIM | M3: SIM | N3: SIM | O3: SIM | P3: SIM | Q3: SIM | R3: SIM | S3: SIM | T3: SIM | U3: SIM | V3: SIM | W3: SIM | X3: SIM | Y3: SIM | Z3: SIM | AA3: SIM | AB3: SIM | AC3: =IF(COUNTIFS($H$1:$AB$1,"x",H3:AB3,"SIM")>0,(D3+E3+F3),0) -> 0 | AD3: =IF(COUNTIFS($H$1:$AB$1,"x",H3:AB3,"SIM")>0,G3) -> 0 | AE3: =COUNTIFS(H3:AB3,"SIM") -> 21
B4: Todas as movimentações financeiras | C4: **Sempre | D4: 0 | F4: 0 | G4: 0 | H4: SIM | I4: SIM | J4: SIM | K4: SIM | L4: SIM | M4: SIM | N4: SIM | O4: SIM | P4: SIM | Q4: SIM | R4: SIM | S4: SIM | T4: SIM | U4: SIM | V4: SIM | W4: SIM | X4: SIM | Y4: SIM | Z4: SIM | AA4: SIM | AB4: SIM | AC4: =IF(COUNTIFS($H$1:$AB$1,"x",H4:AB4,"SIM")>0,(D4+E4+F4),0) -> 0 | AD4: =IF(COUNTIFS($H$1:$AB$1,"x",H4:AB4,"SIM")>0,G4) -> 0 | AE4: =COUNTIFS(H4:AB4,"SIM") -> 21
B5: Todos os fluxos de força de venda | C5: **Sempre | D5: 0 | F5: 0 | G5: 0 | H5: SIM | I5: SIM | J5: SIM | K5: SIM | L5: SIM | M5: SIM | N5: SIM | O5: SIM | P5: SIM | Q5: SIM | R5: SIM | S5: SIM | T5: SIM | U5: SIM | V5: SIM | W5: SIM | X5: SIM | Y5: SIM | Z5: SIM | AA5: SIM | AB5: SIM | AC5: =IF(COUNTIFS($H$1:$AB$1,"x",H5:AB5,"SIM")>0,(D5+E5+F5),0) -> 0 | AD5: =IF(COUNTIFS($H$1:$AB$1,"x",H5:AB5,"SIM")>0,G5) -> 0 | AE5: =COUNTIFS(H5:AB5,"SIM") -> 21
A6: Cadastro básico - País, Estado e Cidade | B6: 1.01 País | C6: **Sempre | G6: 0.020833333 | H6: SIM | I6: SIM | J6: SIM | K6: SIM | L6: SIM | M6: SIM | N6: SIM | O6: SIM | P6: SIM | Q6: SIM | R6: SIM | S6: SIM | T6: SIM | U6: SIM | V6: SIM | W6: SIM | X6: SIM | Y6: SIM | Z6: SIM | AA6: SIM | AB6: SIM | AC6: =IF(COUNTIFS($H$1:$AB$1,"x",H6:AB6,"SIM")>0,(D6+E6+F6),0) -> 0 | AD6: =IF(COUNTIFS($H$1:$AB$1,"x",H6:AB6,"SIM")>0,G6) -> 0.020833333 | AE6: =COUNTIFS(H6:AB6,"SIM") -> 21
B7: 1.02 Unidade Federativa | C7: **Sempre | H7: SIM | I7: SIM | J7: SIM | K7: SIM | L7: SIM | M7: SIM | N7: SIM | O7: SIM | P7: SIM | Q7: SIM | R7: SIM | S7: SIM | T7: SIM | U7: SIM | V7: SIM | W7: SIM | X7: SIM | Y7: SIM | Z7: SIM | AA7: SIM | AB7: SIM | AC7: =IF(COUNTIFS($H$1:$AB$1,"x",H7:AB7,"SIM")>0,(D7+E7+F7),0) -> 0 | AD7: =IF(COUNTIFS($H$1:$AB$1,"x",H7:AB7,"SIM")>0,G7) -> 0 | AE7: =COUNTIFS(H7:AB7,"SIM") -> 21
B8: 1.03 Cidade | C8: **Sempre | H8: SIM | I8: SIM | J8: SIM | K8: SIM | L8: SIM | M8: SIM | N8: SIM | O8: SIM | P8: SIM | Q8: SIM | R8: SIM | S8: SIM | T8: SIM | U8: SIM | V8: SIM | W8: SIM | X8: SIM | Y8: SIM | Z8: SIM | AA8: SIM | AB8: SIM | AC8: =IF(COUNTIFS($H$1:$AB$1,"x",H8:AB8,"SIM")>0,(D8+E8+F8),0) -> 0 | AD8: =IF(COUNTIFS($H$1:$AB$1,"x",H8:AB8,"SIM")>0,G8) -> 0 | AE8: =COUNTIFS(H8:AB8,"SIM") -> 21
A9: Cadastro básico - Unidade de medida | B9: 1.04 Unidade de Medida | C9: **Sempre | G9: 0.010416667 | H9: SIM | I9: SIM | J9: SIM | K9: SIM | L9: SIM | M9: SIM | N9: SIM | O9: SIM | P9: SIM | Q9: SIM | R9: SIM | S9: SIM | T9: SIM | U9: SIM | V9: SIM | W9: SIM | X9: SIM | Y9: SIM | Z9: SIM | AA9: SIM | AB9: SIM | AC9: =IF(COUNTIFS($H$1:$AB$1,"x",H9:AB9,"SIM")>0,(D9+E9+F9),0) -> 0 | AD9: =IF(COUNTIFS($H$1:$AB$1,"x",H9:AB9,"SIM")>0,G9) -> 0.010416667 | AE9: =COUNTIFS(H9:AB9,"SIM") -> 21
A10: Cadastro básico - Parceiro - Parte 1 | B10: 1.05 Parceiro | C10: **Sempre | G10: 0.020833333 | H10: SIM | I10: SIM | J10: SIM | K10: SIM | L10: SIM | M10: SIM | N10: SIM | O10: SIM | P10: SIM | Q10: SIM | R10: SIM | S10: SIM | T10: SIM | U10: SIM | V10: SIM | W10: SIM | X10: SIM | Y10: SIM | Z10: SIM | AA10: SIM | AB10: SIM | AC10: =IF(COUNTIFS($H$1:$AB$1,"x",H10:AB10,"SIM")>0,(D10+E10+F10),0) -> 0 | AD10: =IF(COUNTIFS($H$1:$AB$1,"x",H10:AB10,"SIM")>0,G10) -> 0.020833333 | AE10: =COUNTIFS(H10:AB10,"SIM") -> 21
A11: Cadastro básico - Parceiro - Parte 2 | H11: SIM | I11: SIM | J11: SIM | K11: SIM | L11: SIM | M11: SIM | N11: SIM | O11: SIM | P11: SIM | Q11: SIM | R11: SIM | S11: SIM | T11: SIM | U11: SIM | V11: SIM | W11: SIM | X11: SIM | Y11: SIM | Z11: SIM | AA11: SIM | AB11: SIM | AC11: =IF(COUNTIFS($H$1:$AB$1,"x",H11:AB11,"SIM")>0,(D11+E11+F11),0) -> 0 | AD11: =IF(COUNTIFS($H$1:$AB$1,"x",H11:AB11,"SIM")>0,G11) -> 0 | AE11: =COUNTIFS(H11:AB11,"SIM") -> 21
A12: Cadastro básico - Local - Entidade Empresa | B12: 1.06 Local | C12: **Sempre | D12: 0.66666667 | G12: 0.020833333 | H12: SIM | I12: SIM | J12: SIM | K12: SIM | L12: SIM | M12: SIM | N12: SIM | O12: SIM | P12: SIM | Q12: SIM | R12: SIM | S12: SIM | T12: SIM | U12: SIM | V12: SIM | W12: SIM | X12: SIM | Y12: SIM | Z12: SIM | AA12: SIM | AB12: SIM | AC12: =IF(COUNTIFS($H$1:$AB$1,"x",H12:AB12,"SIM")>0,(D12+E12+F12),0) -> 0.66666667 | AD12: =IF(COUNTIFS($H$1:$AB$1,"x",H12:AB12,"SIM")>0,G12) -> 0.020833333 | AE12: =COUNTIFS(H12:AB12,"SIM") -> 21
A13: Cadastro básico - Local - Entidade Parceiro | H13: SIM | I13: SIM | J13: SIM | K13: SIM | L13: SIM | M13: SIM | N13: SIM | O13: SIM | P13: SIM | Q13: SIM | R13: SIM | S13: SIM | T13: SIM | U13: SIM | V13: SIM | W13: SIM | X13: SIM | Y13: SIM | Z13: SIM | AA13: SIM | AB13: SIM | AC13: =IF(COUNTIFS($H$1:$AB$1,"x",H13:AB13,"SIM")>0,(D13+E13+F13),0) -> 0 | AD13: =IF(COUNTIFS($H$1:$AB$1,"x",H13:AB13,"SIM")>0,G13) -> 0 | AE13: =COUNTIFS(H13:AB13,"SIM") -> 21
A14: Cadastro básico - Local - Entidade Propriedade | H14: SIM | I14: SIM | J14: SIM | K14: SIM | L14: SIM | M14: SIM | N14: SIM | O14: SIM | P14: SIM | Q14: SIM | R14: SIM | S14: SIM | T14: SIM | U14: SIM | V14: SIM | W14: SIM | X14: SIM | Y14: SIM | Z14: SIM | AA14: SIM | AB14: SIM | AC14: =IF(COUNTIFS($H$1:$AB$1,"x",H14:AB14,"SIM")>0,(D14+E14+F14),0) -> 0 | AD14: =IF(COUNTIFS($H$1:$AB$1,"x",H14:AB14,"SIM")>0,G14) -> 0 | AE14: =COUNTIFS(H14:AB14,"SIM") -> 21
A15: Cadastro básico – Empresa | B15: 1.14 Empresa | C15: **Sempre | G15: 0.010416667 | H15: SIM | I15: SIM | J15: SIM | K15: SIM | L15: SIM | M15: SIM | N15: SIM | O15: SIM | P15: SIM | Q15: SIM | R15: SIM | S15: SIM | T15: SIM | U15: SIM | V15: SIM | W15: SIM | X15: SIM | Y15: SIM | Z15: SIM | AA15: SIM | AB15: SIM | AC15: =IF(COUNTIFS($H$1:$AB$1,"x",H15:AB15,"SIM")>0,(D15+E15+F15),0) -> 0 | AD15: =IF(COUNTIFS($H$1:$AB$1,"x",H15:AB15,"SIM")>0,G15) -> 0.010416667 | AE15: =COUNTIFS(H15:AB15,"SIM") -> 21
A16: Cadastro básico - Registrante | B16: 1.15.1 Registrante / Fabricante | C16: *Módulo | H16: NÃO | I16: SIM | J16: SIM | K16: SIM | L16: SIM | M16: SIM | N16: SIM | O16: SIM | P16: SIM | Q16: SIM | R16: SIM | S16: SIM | T16: SIM | U16: SIM | V16: SIM | W16: SIM | X16: SIM | Y16: SIM | Z16: SIM | AA16: SIM | AB16: SIM | AC16: =IF(COUNTIFS($H$1:$AB$1,"x",H16:AB16,"SIM")>0,(D16+E16+F16),0) -> 0 | AD16: =IF(COUNTIFS($H$1:$AB$1,"x",H16:AB16,"SIM")>0,G16) -> 0 | AE16: =COUNTIFS(H16:AB16,"SIM") -> 20
A17: Cadastro básico - Fornecedor | B17: 1.15.2 Fornecedor | C17: *Módulo | H17: NÃO | I17: SIM | J17: SIM | K17: SIM | L17: SIM | M17: SIM | N17: SIM | O17: SIM | P17: SIM | Q17: SIM | R17: SIM | S17: SIM | T17: SIM | U17: SIM | V17: SIM | W17: SIM | X17: SIM | Y17: SIM | Z17: SIM | AA17: SIM | AB17: SIM | AC17: =IF(COUNTIFS($H$1:$AB$1,"x",H17:AB17,"SIM")>0,(D17+E17+F17),0) -> 0 | AD17: =IF(COUNTIFS($H$1:$AB$1,"x",H17:AB17,"SIM")>0,G17) -> 0 | AE17: =COUNTIFS(H17:AB17,"SIM") -> 20
A18: Cadastro básico - Filial | B18: 1.15 Filial | C18: **Sempre | G18: 0.017361111 | H18: SIM | I18: SIM | J18: SIM | K18: SIM | L18: SIM | M18: SIM | N18: SIM | O18: SIM | P18: SIM | Q18: SIM | R18: SIM | S18: SIM | T18: SIM | U18: SIM | V18: SIM | W18: SIM | X18: SIM | Y18: SIM | Z18: SIM | AA18: SIM | AB18: SIM | AC18: =IF(COUNTIFS($H$1:$AB$1,"x",H18:AB18,"SIM")>0,(D18+E18+F18),0) -> 0 | AD18: =IF(COUNTIFS($H$1:$AB$1,"x",H18:AB18,"SIM")>0,G18) -> 0.017361111 | AE18: =COUNTIFS(H18:AB18,"SIM") -> 21
A19: Cadastro básico - Pessoa física e jurídica - Fluxo 1 | B19: 1.16 Pessoa Física e 1.17 Pessoa Jurídica | C19: **Sempre | G19: 0.041666667 | H19: SIM | I19: SIM | J19: SIM | K19: SIM | L19: SIM | M19: SIM | N19: SIM | O19: SIM | P19: SIM | Q19: SIM | R19: SIM | S19: SIM | T19: SIM | U19: SIM | V19: SIM | W19: SIM | X19: SIM | Y19: SIM | Z19: SIM | AA19: SIM | AB19: SIM | AC19: =IF(COUNTIFS($H$1:$AB$1,"x",H19:AB19,"SIM")>0,(D19+E19+F19),0) -> 0 | AD19: =IF(COUNTIFS($H$1:$AB$1,"x",H19:AB19,"SIM")>0,G19) -> 0.041666667 | AE19: =COUNTIFS(H19:AB19,"SIM") -> 21
A20: Cadastro básico - Pessoa física - Fluxo 2 | H20: SIM | I20: SIM | J20: SIM | K20: SIM | L20: SIM | M20: SIM | N20: SIM | O20: SIM | P20: SIM | Q20: SIM | R20: SIM | S20: SIM | T20: SIM | U20: SIM | V20: SIM | W20: SIM | X20: SIM | Y20: SIM | Z20: SIM | AA20: SIM | AB20: SIM | AC20: =IF(COUNTIFS($H$1:$AB$1,"x",H20:AB20,"SIM")>0,(D20+E20+F20),0) -> 0 | AD20: =IF(COUNTIFS($H$1:$AB$1,"x",H20:AB20,"SIM")>0,G20) -> 0 | AE20: =COUNTIFS(H20:AB20,"SIM") -> 21
A21: Cadastro básico - Pessoa jurídica - Fluxo 3 | AC21: =IF(COUNTIFS($H$1:$AB$1,"x",H21:AB21,"SIM")>0,(D21+E21+F21),0) -> 0 | AD21: =IF(COUNTIFS($H$1:$AB$1,"x",H21:AB21,"SIM")>0,G21) -> FALSE | AE21: =COUNTIFS(H21:AB21,"SIM") -> 0
A22: Cadastro básico - Produto e produto classe | B22: 1.08 Produto e 1.10 Produto Classe | C22: *Módulo | D22: 0.66666667 | G22: 0.020833333 | H22: NÃO | I22: SIM | J22: SIM | K22: SIM | L22: SIM | M22: SIM | N22: SIM | O22: SIM | P22: SIM | Q22: SIM | R22: SIM | S22: SIM | T22: SIM | U22: SIM | V22: SIM | W22: SIM | X22: SIM | Y22: SIM | Z22: SIM | AA22: SIM | AB22: SIM | AC22: =IF(COUNTIFS($H$1:$AB$1,"x",H22:AB22,"SIM")>0,(D22+E22+F22),0) -> 0.66666667 | AD22: =IF(COUNTIFS($H$1:$AB$1,"x",H22:AB22,"SIM")>0,G22) -> 0.020833333 | AE22: =COUNTIFS(H22:AB22,"SIM") -> 20
A23: Cadastro básico - Classe de produto | B23: 1.09 Classe de Produto | C23: *Módulo | G23: 0.020833333 | H23: NÃO | I23: SIM | J23: SIM | K23: SIM | L23: SIM | M23: SIM | N23: SIM | O23: SIM | P23: SIM | Q23: SIM | R23: SIM | S23: SIM | T23: SIM | U23: SIM | V23: SIM | W23: SIM | X23: SIM | Y23: SIM | Z23: SIM | AA23: SIM | AB23: SIM | AC23: =IF(COUNTIFS($H$1:$AB$1,"x",H23:AB23,"SIM")>0,(D23+E23+F23),0) -> 0 | AD23: =IF(COUNTIFS($H$1:$AB$1,"x",H23:AB23,"SIM")>0,G23) -> 0.020833333 | AE23: =COUNTIFS(H23:AB23,"SIM") -> 20
A24: Movimentação financeira - Local nota fiscal | B24: 3.1 Local Nota Fiscal | C24: *Módulo | D24: 0.29166667 | G24: 0.083333333 | H24: NÃO | I24: SIM | J24: NÃO | K24: NÃO | L24: NÃO | M24: SIM | N24: NÃO | O24: SIM | P24: SIM | Q24: SIM | R24: SIM | S24: NÃO | T24: NÃO | U24: SIM | V24: NÃO | W24: NÃO | X24: SIM | Y24: NÃO | Z24: NÃO | AA24: NÃO | AB24: NÃO | AC24: =IF(COUNTIFS($H$1:$AB$1,"x",H24:AB24,"SIM")>0,(D24+E24+F24),0) -> 0 | AD24: =IF(COUNTIFS($H$1:$AB$1,"x",H24:AB24,"SIM")>0,G24) -> FALSE | AE24: =COUNTIFS(H24:AB24,"SIM") -> 8
A25: Movimentação financeira - Faturamento mensal - Parte 1 | B25: 3.2 Pedidos em Carteira (Fat. Mensal) | C25: *Módulo | D25: 0.020833333 | F25: 0.010416667 | G25: 0.16666667 | H25: NÃO | I25: NÃO | J25: NÃO | K25: NÃO | L25: NÃO | M25: SIM | N25: SIM | O25: SIM | P25: NÃO | Q25: SIM | R25: NÃO | S25: NÃO | T25: NÃO | U25: NÃO | V25: NÃO | W25: NÃO | X25: NÃO | Y25: NÃO | Z25: NÃO | AA25: NÃO | AB25: NÃO | AC25: =IF(COUNTIFS($H$1:$AB$1,"x",H25:AB25,"SIM")>0,(D25+E25+F25),0) -> 0 | AD25: =IF(COUNTIFS($H$1:$AB$1,"x",H25:AB25,"SIM")>0,G25) -> FALSE | AE25: =COUNTIFS(H25:AB25,"SIM") -> 4
A26: Movimentação financeira - Faturamento mensal - Parte 2 | AC26: =IF(COUNTIFS($H$1:$AB$1,"x",H26:AB26,"SIM")>0,(D26+E26+F26),0) -> 0 | AD26: =IF(COUNTIFS($H$1:$AB$1,"x",H26:AB26,"SIM")>0,G26) -> FALSE | AE26: =COUNTIFS(H26:AB26,"SIM") -> 0
A27: Cadastro básico - Usuários | B27: 1.11 Usuário | C27: *Qualifica | G27: 0.0069444444 | H27: SIM | I27: SIM | J27: NÃO | K27: NÃO | L27: SIM | M27: NÃO | N27: NÃO | O27: NÃO | P27: NÃO | Q27: NÃO | R27: NÃO | S27: NÃO | T27: NÃO | U27: NÃO | V27: SIM | W27: NÃO | X27: NÃO | Y27: NÃO | Z27: NÃO | AA27: NÃO | AB27: NÃO | AC27: =IF(COUNTIFS($H$1:$AB$1,"x",H27:AB27,"SIM")>0,(D27+E27+F27),0) -> 0 | AD27: =IF(COUNTIFS($H$1:$AB$1,"x",H27:AB27,"SIM")>0,G27) -> 0.0069444444 | AE27: =COUNTIFS(H27:AB27,"SIM") -> 4
A28: Cadastro básico - Usuário empresa, filial e parceiro | B28: 1.28 Usuário Filial | C28: *Qualifica | G28: 0.020833333 | H28: SIM | I28: =$H$27 -> SIM | J28: NÃO | K28: NÃO | L28: SIM | M28: NÃO | N28: NÃO | O28: NÃO | P28: NÃO | Q28: NÃO | R28: NÃO | S28: NÃO | T28: NÃO | U28: NÃO | V28: SIM | W28: NÃO | X28: NÃO | Y28: NÃO | Z28: NÃO | AA28: NÃO | AB28: NÃO | AC28: =IF(COUNTIFS($H$1:$AB$1,"x",H28:AB28,"SIM")>0,(D28+E28+F28),0) -> 0 | AD28: =IF(COUNTIFS($H$1:$AB$1,"x",H28:AB28,"SIM")>0,G28) -> 0.020833333 | AE28: =COUNTIFS(H28:AB28,"SIM") -> 4
B29: 1.29 Usuário Empresa | C29: *Qualifica | H29: SIM | I29: =$H$27 -> SIM | J29: NÃO | K29: NÃO | L29: SIM | M29: NÃO | N29: NÃO | O29: NÃO | P29: NÃO | Q29: NÃO | R29: NÃO | S29: NÃO | T29: NÃO | U29: NÃO | V29: SIM | W29: NÃO | X29: NÃO | Y29: NÃO | Z29: NÃO | AA29: NÃO | AB29: NÃO | AC29: =IF(COUNTIFS($H$1:$AB$1,"x",H29:AB29,"SIM")>0,(D29+E29+F29),0) -> 0 | AD29: =IF(COUNTIFS($H$1:$AB$1,"x",H29:AB29,"SIM")>0,G29) -> 0 | AE29: =COUNTIFS(H29:AB29,"SIM") -> 4
B30: 1.28 Usuário Parceiro | C30: *Qualifica | H30: SIM | I30: =$H$27 -> SIM | J30: NÃO | K30: NÃO | L30: SIM | M30: NÃO | N30: NÃO | O30: NÃO | P30: NÃO | Q30: NÃO | R30: NÃO | S30: NÃO | T30: NÃO | U30: NÃO | V30: SIM | W30: NÃO | X30: NÃO | Y30: NÃO | Z30: NÃO | AA30: NÃO | AB30: NÃO | AC30: =IF(COUNTIFS($H$1:$AB$1,"x",H30:AB30,"SIM")>0,(D30+E30+F30),0) -> 0 | AD30: =IF(COUNTIFS($H$1:$AB$1,"x",H30:AB30,"SIM")>0,G30) -> 0 | AE30: =COUNTIFS(H30:AB30,"SIM") -> 4
B31: 1.27 Usuário Produto | C31: *Qualifica | D31: 0.0069444444 | H31: NÃO | I31: NÃO | J31: NÃO | K31: NÃO | L31: NÃO | M31: NÃO | N31: NÃO | O31: NÃO | P31: NÃO | Q31: NÃO | R31: NÃO | S31: NÃO | T31: NÃO | U31: NÃO | V31: NÃO | W31: NÃO | X31: NÃO | Y31: NÃO | Z31: NÃO | AA31: NÃO | AB31: NÃO | AC31: =IF(COUNTIFS($H$1:$AB$1,"x",H31:AB31,"SIM")>0,(D31+E31+F31),0) -> 0 | AD31: =IF(COUNTIFS($H$1:$AB$1,"x",H31:AB31,"SIM")>0,G31) -> FALSE | AE31: =COUNTIFS(H31:AB31,"SIM") -> 0
A32: Cadastro básico - Cultura | B32: 1.12 Cultura | C32: *Qualifica | G32: 0.0069444444 | H32: SIM | I32: SIM | J32: SIM | K32: SIM | L32: SIM | M32: SIM | N32: NÃO | O32: NÃO | P32: NÃO | Q32: NÃO | R32: NÃO | S32: NÃO | T32: NÃO | U32: NÃO | V32: SIM | W32: NÃO | X32: NÃO | Y32: NÃO | Z32: NÃO | AA32: NÃO | AB32: NÃO | AC32: =IF(COUNTIFS($H$1:$AB$1,"x",H32:AB32,"SIM")>0,(D32+E32+F32),0) -> 0 | AD32: =IF(COUNTIFS($H$1:$AB$1,"x",H32:AB32,"SIM")>0,G32) -> 0.0069444444 | AE32: =COUNTIFS(H32:AB32,"SIM") -> 7
A33: Cadastro básico - Safra | B33: 1.13 Safra | C33: *Qualifica | G33: 0.020833333 | H33: NÃO | I33: SIM | J33: SIM | K33: SIM | L33: SIM | M33: SIM | N33: NÃO | O33: NÃO | P33: NÃO | Q33: SIM | R33: NÃO | S33: NÃO | T33: NÃO | U33: NÃO | V33: SIM | W33: NÃO | X33: NÃO | Y33: NÃO | Z33: NÃO | AA33: NÃO | AB33: NÃO | AC33: =IF(COUNTIFS($H$1:$AB$1,"x",H33:AB33,"SIM")>0,(D33+E33+F33),0) -> 0 | AD33: =IF(COUNTIFS($H$1:$AB$1,"x",H33:AB33,"SIM")>0,G33) -> 0.020833333 | AE33: =COUNTIFS(H33:AB33,"SIM") -> 7
A34: Cadastro básico - Região | B34: 1.19 Região | C34: *Qualifica | G34: 0.010416667 | H34: SIM | I34: SIM | J34: SIM | K34: SIM | L34: SIM | M34: SIM | N34: NÃO | O34: NÃO | P34: NÃO | Q34: NÃO | R34: NÃO | S34: NÃO | T34: NÃO | U34: NÃO | V34: SIM | W34: NÃO | X34: NÃO | Y34: NÃO | Z34: NÃO | AA34: NÃO | AB34: NÃO | AC34: =IF(COUNTIFS($H$1:$AB$1,"x",H34:AB34,"SIM")>0,(D34+E34+F34),0) -> 0 | AD34: =IF(COUNTIFS($H$1:$AB$1,"x",H34:AB34,"SIM")>0,G34) -> 0.010416667 | AE34: =COUNTIFS(H34:AB34,"SIM") -> 7
A35: Cadastro básico - Região local | B35: 1.20 Região Local | C35: *Qualifica | G35: 0.017361111 | H35: SIM | I35: SIM | J35: SIM | K35: SIM | L35: SIM | M35: SIM | N35: NÃO | O35: NÃO | P35: NÃO | Q35: NÃO | R35: NÃO | S35: NÃO | T35: NÃO | U35: NÃO | V35: SIM | W35: NÃO | X35: NÃO | Y35: NÃO | Z35: NÃO | AA35: NÃO | AB35: NÃO | AC35: =IF(COUNTIFS($H$1:$AB$1,"x",H35:AB35,"SIM")>0,(D35+E35+F35),0) -> 0 | AD35: =IF(COUNTIFS($H$1:$AB$1,"x",H35:AB35,"SIM")>0,G35) -> 0.017361111 | AE35: =COUNTIFS(H35:AB35,"SIM") -> 7
